Workbook

Sheet PORTADA Y DATOS
A3: DATOS GENERALES
A4: Dependencia/Contratante/Cliente | C4: Luis Alberto Gamboa Ruelas
A5: Obra | B5: Casa Altata
A6: Dirección | B6: Altata, Navolato, Sinaloa.
A7: Contratista | B7: Luis Alberto Gamboa Ruelas
A8: Responsable | B8: Luis D. Peregrina García
A9: Fecha de inicio | B9: Sin definir por contratista
A10: Tipo de contrato | B10: Precio Unitario
A11: Supervisor | B11: Definido por parte contratante

Sheet PRE_LIM_01
A1: NÚMEROS GENERADORES
A3: ='PORTADA Y DATOS'!A7 -> Contratista | B3: ='PORTADA Y DATOS'!B7 -> Luis Alberto Gamboa Ruelas | E3: ='PORTADA Y DATOS'!A6 -> Dirección | F3: ='PORTADA Y DATOS'!B6 -> Altata, Navolato, Sinaloa. | J3: =A1 -> NÚMEROS GENERADORES
A4: ='PORTADA Y DATOS'!A5 -> Obra | B4: ='PORTADA Y DATOS'!B5 -> Casa Altata | E4: ='PORTADA Y DATOS'!A4 -> Dependencia/Contratante/Cliente | H4: Logotipo | J4: 1
J5: Periodo
A6: ='PORTADA Y DATOS'!A10 -> Tipo de contrato | C6: Partida | E6: Limpiezas de terreno | I6: HOJA: 1 | J6: De: 11/10/2021 | K6: Al: 16/10/2021
A7: ='PORTADA Y DATOS'!B10 -> Precio Unitario | I7: DE: 1 | J7: ='PORTADA Y DATOS'!A9 -> Fecha de inicio | K7: ='PORTADA Y DATOS'!B9 -> Sin definir por contratista
A8: CLAVE | B8: CONCEPTO | C8: L O C A L I Z A C I O N | F8: LARGO | G8: ANCHO | H8: ALTO | I8: PZAS | J8: UNIDAD | K8: TOTAL
C9: EJE | D9: TRAMO
A10: Responsable de la empresa | F10: ='PORTADA Y DATOS'!B11 -> Definido por parte contratante
A11: PRE_LIM_01 | B11: Limpieza de terreno por medios mecánicos para trabajos preliminares. Incluye: desmonte, despalme, apile de material producto de los trabajos, herramienta menor, equipo, mano de obra y todo lo necesario para su correcta ejecución. | C11: A-G | D11: 1 | E11: 9 | F11: 16 | G11: 7.5 | H11: 1 | J11: m2 | K11: =F11*G11 -> 120
K12: =F12*H12 -> 0
K13: =F13*H13 -> 0
K14: =F14*H14 -> 0
K15: =F15*H15 -> 0
K16: =F16*H16 -> 0
K17: =F17*H17 -> 0
K18: =F18*H18 -> 0
K19: =F19*H19 -> 0
K20: =F20*H20 -> 0
K21: =F21*H21 -> 0
K22: =F22*H22 -> 0
K23: =F23*H23 -> 0
... K37: =F37*H37 -> 0
I39: Total | J39: =J11 -> m2 | K39: =SUM(K11:K38) -> 120
A45: Elaboró | D45: Revisó | I45: Vo. Bo.
A46: ='PORTADA Y DATOS'!A11 -> Supervisor | D46: ='PORTADA Y DATOS'!A4 -> Dependencia/Contratante/Cliente | I46: ='PORTADA Y DATOS'!A7 -> Contratista
A47: ='PORTADA Y DATOS'!B11 -> Definido por parte contratante | D47: ='PORTADA Y DATOS'!C4 -> Luis Alberto Gamboa Ruelas | I47: ='PORTADA Y DATOS'!B7 -> Luis Alberto Gamboa Ruelas

Sheet PRE_TYN_01
A1: NÚMEROS GENERADORES
A3: ='PORTADA Y DATOS'!A7 -> Contratista | B3: ='PORTADA Y DATOS'!B7 -> Luis Alberto Gamboa Ruelas | E3: ='PORTADA Y DATOS'!A6 -> Dirección | F3: ='PORTADA Y DATOS'!B6 -> Altata, Navolato, Sinaloa. | J3: =A1 -> NÚMEROS GENERADORES
A4: ='PORTADA Y DATOS'!A5 -> Obra | B4: ='PORTADA Y DATOS'!B5 -> Casa Altata | E4: ='PORTADA Y DATOS'!A4 -> Dependencia/Contratante/Cliente | H4: Logotipo | J4: 2
J5: Periodo
A6: ='PORTADA Y DATOS'!A10 -> Tipo de contrato | C6: Partida | E6: Trazo y nivelación | I6: HOJA: 1 | J6: De: 11/10/2021 | K6: Al: 16/10/2021
A7: ='PORTADA Y DATOS'!B10 -> Precio Unitario | I7: DE: 1 | J7: ='PORTADA Y DATOS'!A9 -> Fecha de inicio | K7: ='PORTADA Y DATOS'!B9 -> Sin definir por contratista
A8: CLAVE | B8: CONCEPTO | C8: L O C A L I Z A C I O N | F8: LARGO | G8: ANCHO | H8: ALTO | I8: PZAS | J8: UNIDAD | K8: TOTAL
C9: EJE | D9: TRAMO
A10: Responsable de la empresa | F10: ='PORTADA Y DATOS'!B11 -> Definido por parte contratante
A11: PRE_TYN_01 | B11: Trazo y nivelación por medios manuales para trabajos preliminares. Incluye: material, mano de obra, herramienta menor y todo lo necesario para su correcta ejecución. | C11: A-G | D11: 1 | E11: 9 | F11: 16 | G11: 7.5 | H11: 1 | J11: m2 | K11: =F11*G11 -> 120
K12: =F12*H12 -> 0
K13: =F13*H13 -> 0
K14: =F14*H14 -> 0
K15: =F15*H15 -> 0
K16: =F16*H16 -> 0
K17: =F17*H17 -> 0
K18: =F18*H18 -> 0
K19: =F19*H19 -> 0
K20: =F20*H20 -> 0
K21: =F21*H21 -> 0
K22: =F22*H22 -> 0
K23: =F23*H23 -> 0
... K37: =F37*H37 -> 0
I39: Total | J39: =J11 -> m2 | K39: =SUM(K11:K38) -> 120
A45: Elaboró | D45: Revisó | I45: Vo. Bo.
A46: ='PORTADA Y DATOS'!A11 -> Supervisor | D46: ='PORTADA Y DATOS'!A4 -> Dependencia/Contratante/Cliente | I46: ='PORTADA Y DATOS'!A7 -> Contratista
A47: ='PORTADA Y DATOS'!B11 -> Definido por parte contratante | D47: ='PORTADA Y DATOS'!C4 -> Luis Alberto Gamboa Ruelas | I47: ='PORTADA Y DATOS'!B7 -> Luis Alberto Gamboa Ruelas

Sheet PRE_OSP_01
A1: NÚMEROS GENERADORES
A3: ='PORTADA Y DATOS'!A7 -> Contratista | B3: ='PORTADA Y DATOS'!B7 -> Luis Alberto Gamboa Ruelas | E3: ='PORTADA Y DATOS'!A6 -> Dirección | F3: ='PORTADA Y DATOS'!B6 -> Altata, Navolato, Sinaloa. | J3: =A1 -> NÚMEROS GENERADORES
A4: ='PORTADA Y DATOS'!A5 -> Obra | B4: ='PORTADA Y DATOS'!B5 -> Casa Altata | E4: ='PORTADA Y DATOS'!A4 -> Dependencia/Contratante/Cliente | H4: Logotipo | J4: 2
J5: Periodo
A6: ='PORTADA Y DATOS'!A10 -> Tipo de contrato | C6: Partida | E6: Trazo y nivelación | I6: HOJA: 1 | J6: De: 11/10/2021 | K6: Al: 16/10/2021
A7: ='PORTADA Y DATOS'!B10 -> Precio Unitario | I7: DE: 1 | J7: ='PORTADA Y DATOS'!A9 -> Fecha de inicio | K7: ='PORTADA Y DATOS'!B9 -> Sin definir por contratista
A8: CLAVE | B8: CONCEPTO | C8: L O C A L I Z A C I O N | F8: LARGO | G8: ANCHO | H8: ALTO | I8: PZAS | J8: UNIDAD | K8: TOTAL
C9: EJE | D9: TRAMO
A10: Responsable de la empresa | F10: ='PORTADA Y DATOS'!B11 -> Definido por parte contratante
A11: PRE_OSP_01 | B11: Protección provisional de 2.50m fabricado con malla electrosoldada 6-6,8'8', con bastidor de polín 3.5"x3.5"x10' y anclaje con dado de sección 0.20x0.20x0.50m. Incluye material, mano de obra, herramienta menor y todo lo necesario para su correcta ejecución. | C11: A | D11: 8 | E11: 9 | F11: 5.38 | G11: 1 | H11: 1 | J11: mL | K11: =F11*G11 -> 5.38
C12: G | D12: 8 | E12: 9 | F12: 5.88 | G12: 1 | H12: 1 | K12: =F12*H12 -> 5.88
C13: 9 | D13: A | E13: G | F13: 7.5 | G13: 1 | H13: 1 | K13: =F13*H13 -> 7.5
K14: =F14*H14 -> 0
K15: =F15*H15 -> 0
K16: =F16*H16 -> 0
K17: =F17*H17 -> 0
K18: =F18*H18 -> 0
K19: =F19*H19 -> 0
K20: =F20*H20 -> 0
K21: =F21*H21 -> 0
K22: =F22*H22 -> 0
K23: =F23*H23 -> 0
K24: =F24*H24 -> 0
K25: =F25*H25 -> 0
... K37: =F37*H37 -> 0
I39: Total | J39: =J11 -> mL | K39: =SUM(K11:K38) -> 18.76
A45: Elaboró | D45: Revisó | I45: Vo. Bo.
A46: ='PORTADA Y DATOS'!A11 -> Supervisor | D46: ='PORTADA Y DATOS'!A4 -> Dependencia/Contratante/Cliente | I46: ='PORTADA Y DATOS'!A7 -> Contratista
A47: ='PORTADA Y DATOS'!B11 -> Definido por parte contratante | D47: ='PORTADA Y DATOS'!C4 -> Luis Alberto Gamboa Ruelas | I47: ='PORTADA Y DATOS'!B7 -> Luis Alberto Gamboa Ruelas

Sheet CIM_PCP_01
A1: NÚMEROS GENERADORES
A3: ='PORTADA Y DATOS'!A7 -> Contratista | B3: ='PORTADA Y DATOS'!B7 -> Luis Alberto Gamboa Ruelas | E3: ='PORTADA Y DATOS'!A6 -> Dirección | F3: ='PORTADA Y DATOS'!B6 -> Altata, Navolato, Sinaloa. | J3: =A1 -> NÚMEROS GENERADORES
A4: ='PORTADA Y DATOS'!A5 -> Obra | B4: ='PORTADA Y DATOS'!B5 -> Casa Altata | E4: ='PORTADA Y DATOS'!A4 -> Dependencia/Contratante/Cliente | H4: Logotipo | J4: 4
J5: Periodo
A6: ='PORTADA Y DATOS'!A10 -> Tipo de contrato | C6: Partida | E6: Plantillas concreto pobre en CT-1 | I6: HOJA: 1 | J6: De: 11/10/2021 | K6: Al: 16/10/2021
A7: ='PORTADA Y DATOS'!B10 -> Precio Unitario | I7: DE: 1 | J7: ='PORTADA Y DATOS'!A9 -> Fecha de inicio | K7: ='PORTADA Y DATOS'!B9 -> Sin definir por contratista
A8: CLAVE | B8: CONCEPTO | C8: L O C A L I Z A C I O N | F8: LARGO | G8: ANCHO | H8: ALTO | I8: PZAS | J8: UNIDAD | K8: TOTAL
C9: EJE | D9: TRAMO
A10: Responsable de la empresa | F10: ='PORTADA Y DATOS'!B11 -> Definido por parte contratante
A11: CIM_PCP_01 | B11: Plantilla de 5 cm para desplante de cimentación en CT-1 de concreto fc = 100 kg/cm2, fabricado en obra con revolvedora. Incluye: nivelación del terreno para desplante, compactacion del fondo, cimbra en fronteras, colado y curado con agua. | C11: A | D11: 3 | E11: 8 | F11: 8.38 | J11: m2 | K11: =F11 -> 8.38
C12: B | D12: 3 | E12: 4 | F12: 1 | K12: =F12 -> 1
C13: C | D13: 7 | E13: 8 | F13: 0.65 | K13: =F13 -> 0.65
C14: D | D14: 2 | E14: 5 | F14: 3.33 | K14: =F14 -> 3.33
C15: D | D15: 6 | E15: 7 | F15: 3.15 | K15: =F15 -> 3.15
C16: E | D16: 1 | E16: 2 | F16: 1.88 | K16: =F16 -> 1.88
C17: F | D17: 5 | E17: 6 | F17: 1.95 | K17: =F17 -> 1.95
C18: G | D18: 1 | E18: 7 | F18: 10.25 | K18: =F18 -> 10.25
C19: 1 | D19: E | E19: G | F19: 2.59 | K19: =F19 -> 2.59
C20: 2 | D20: D | E20: G | F20: 3.3 | K20: =F20 -> 3.3
C21: 3 | D21: A | E21: B | F21: 2.75 | K21: =F21 -> 2.75
C22: 4 | D22: B | E22: D | F22: 1.85 | K22: =F22 -> 1.85
C23: 5 | D23: A | E23: G | F23: 7.5 | K23: =F23 -> 7.5
C24: 6 | D24: A | E24: G | F24: 7.5 | K24: =F24 -> 7.5
C25: 7 | D25: C | E25: G | F25: 3.9 | K25: =F25 -> 3.9
C26: 8 | D26: A | E26: C | F26: 3.8 | K26: =F26 -> 3.8
K27: =F27 -> 0
K28: =F28 -> 0
K29: =F29 -> 0
K30: =F30 -> 0
K31: =F31 -> 0
K32: =F32 -> 0
K33: =F33 -> 0
K34: =F34*H34 -> 0
K35: =F35*H35 -> 0
K36: =F36*H36 -> 0
K37: =F37*H37 -> 0
I39: Total | J39: =J11 -> m2 | K39: =SUM(K11:K38) -> 63.78
A45: Elaboró | D45: Revisó | I45: Vo. Bo.
A46: ='PORTADA Y DATOS'!A11 -> Supervisor | D46: ='PORTADA Y DATOS'!A4 -> Dependencia/Contratante/Cliente | I46: ='PORTADA Y DATOS'!A7 -> Contratista
A47: ='PORTADA Y DATOS'!B11 -> Definido por parte contratante | D47: ='PORTADA Y DATOS'!C4 -> Luis Alberto Gamboa Ruelas | I47: ='PORTADA Y DATOS'!B7 -> Luis Alberto Gamboa Ruelas

Sheet CIM_PCP_01 (2)
A1: NÚMEROS GENERADORES
A3: ='PORTADA Y DATOS'!A7 -> Contratista | B3: ='PORTADA Y DATOS'!B7 -> Luis Alberto Gamboa Ruelas | E3: ='PORTADA Y DATOS'!A6 -> Dirección | F3: ='PORTADA Y DATOS'!B6 -> Altata, Navolato, Sinaloa. | J3: =A1 -> NÚMEROS GENERADORES
A4: ='PORTADA Y DATOS'!A5 -> Obra | B4: ='PORTADA Y DATOS'!B5 -> Casa Altata | E4: ='PORTADA Y DATOS'!A4 -> Dependencia/Contratante/Cliente | H4: Logotipo | J4: 4
J5: Periodo
A6: ='PORTADA Y DATOS'!A10 -> Tipo de contrato | C6: Partida | E6: Plantillas concreto pobre en losa | I6: HOJA: 1 | J6: De: 11/10/2021 | K6: Al: 16/10/2021
A7: ='PORTADA Y DATOS'!B10 -> Precio Unitario | I7: DE: 1 | J7: ='PORTADA Y DATOS'!A9 -> Fecha de inicio | K7: ='PORTADA Y DATOS'!B9 -> Sin definir por contratista
A8: CLAVE | B8: CONCEPTO | C8: L O C A L I Z A C I O N | F8: LARGO | G8: ANCHO | H8: ALTO | I8: PZAS | J8: UNIDAD | K8: TOTAL
C9: EJE | D9: TRAMO
A10: Responsable de la empresa | F10: ='PORTADA Y DATOS'!B11 -> Definido por parte contratante
A11: CIM_PCP_01 | B11: Plantilla de 5 cm para desplante de cimentación por losa de concreto fc = 100 kg/cm2, fabricado en obra con revolvedora. Incluye: nivelación del terreno para desplante, compactacion del fondo, cimbra en fronteras, colado y curado con agua. | C11: A-G | D11: 1 | E11: 8 | J11: m2 | K11: 66.42
K12: =F12*H12 -> 0
D13: Nota: | E13: Se toma el valor como plataforma completa, por lo que el desgloce por ejes no se indica | K13: =F13*H13 -> 0
K14: =F14*H14 -> 0
K15: =F15*H15 -> 0
K16: =F16*H16 -> 0
K17: =F17*H17 -> 0
K18: =F18*H18 -> 0
K19: =F19*H19 -> 0
K20: =F20*H20 -> 0
K21: =F21*H21 -> 0
K22: =F22*H22 -> 0
K23: =F23*H23 -> 0
K24: =F24*H24 -> 0
K25: =F25*H25 -> 0
... K37: =F37*H37 -> 0
I39: Total | J39: =J11 -> m2 | K39: =SUM(K11:K38) -> 66.42
A45: Elaboró | D45: Revisó | I45: Vo. Bo.
A46: ='PORTADA Y DATOS'!A11 -> Supervisor | D46: ='PORTADA Y DATOS'!A4 -> Dependencia/Contratante/Cliente | I46: ='PORTADA Y DATOS'!A7 -> Contratista
A47: ='PORTADA Y DATOS'!B11 -> Definido por parte contratante | D47: ='PORTADA Y DATOS'!C4 -> Luis Alberto Gamboa Ruelas | I47: ='PORTADA Y DATOS'!B7 -> Luis Alberto Gamboa Ruelas

Sheet CIM_PCP_01 (3)
A1: NÚMEROS GENERADORES
A3: ='PORTADA Y DATOS'!A7 -> Contratista | B3: ='PORTADA Y DATOS'!B7 -> Luis Alberto Gamboa Ruelas | E3: ='PORTADA Y DATOS'!A6 -> Dirección | F3: ='PORTADA Y DATOS'!B6 -> Altata, Navolato, Sinaloa. | J3: =A1 -> NÚMEROS GENERADORES
A4: ='PORTADA Y DATOS'!A5 -> Obra | B4: ='PORTADA Y DATOS'!B5 -> Casa Altata | E4: ='PORTADA Y DATOS'!A4 -> Dependencia/Contratante/Cliente | H4: Logotipo | J4: 4
J5: Periodo
A6: ='PORTADA Y DATOS'!A10 -> Tipo de contrato | C6: Partida | E6: Plantillas concreto pobre en ZC-1 | I6: HOJA: 1 | J6: De: 11/10/2021 | K6: Al: 16/10/2021
A7: ='PORTADA Y DATOS'!B10 -> Precio Unitario | I7: DE: 1 | J7: ='PORTADA Y DATOS'!A9 -> Fecha de inicio | K7: ='PORTADA Y DATOS'!B9 -> Sin definir por contratista
A8: CLAVE | B8: CONCEPTO | C8: L O C A L I Z A C I O N | F8: LARGO | G8: ANCHO | H8: ALTO | I8: PZAS | J8: UNIDAD | K8: TOTAL
C9: EJE | D9: TRAMO
A10: Responsable de la empresa | F10: ='PORTADA Y DATOS'!B11 -> Definido por parte contratante
A11: CIM_PCP_01 | B11: Plantilla de 5 cm para desplante de cimentación por zapata aislada de concreto fc = 100 kg/cm2, fabricado en obra con revolvedora. Incluye: nivelación del terreno para desplante, compactacion del fondo, cimbra en fronteras, colado y curado con agua. | C11: A | D11: 1 | E11: 3 | F11: 2.32 | G11: 0.75 | J11: mL | K11: =(F11*G11) -> 1.74
C12: 1 | D12: A | E12: E | F12: 4.92 | G12: 0.75 | K12: =(F12*G12) -> 3.69
K13: =F13*H13 -> 0
K14: =F14*H14 -> 0
K15: =F15*H15 -> 0
K16: =F16*H16 -> 0
K17: =F17*H17 -> 0
K18: =F18*H18 -> 0
K19: =F19*H19 -> 0
K20: =F20*H20 -> 0
K21: =F21*H21 -> 0
K22: =F22*H22 -> 0
K23: =F23*H23 -> 0
K24: =F24*H24 -> 0
... K37: =F37*H37 -> 0
I39: Total | J39: =J11 -> mL | K39: =SUM(K11:K38) -> 5.43
A45: Elaboró | D45: Revisó | I45: Vo. Bo.
A46: ='PORTADA Y DATOS'!A11 -> Supervisor | D46: ='PORTADA Y DATOS'!A4 -> Dependencia/Contratante/Cliente | I46: ='PORTADA Y DATOS'!A7 -> Contratista
A47: ='PORTADA Y DATOS'!B11 -> Definido por parte contratante | D47: ='PORTADA Y DATOS'!C4 -> Luis Alberto Gamboa Ruelas | I47: ='PORTADA Y DATOS'!B7 -> Luis Alberto Gamboa Ruelas

Sheet CIM_IMP_CIM_02
A1: NÚMEROS GENERADORES
A3: ='PORTADA Y DATOS'!A7 -> Contratista | B3: ='PORTADA Y DATOS'!B7 -> Luis Alberto Gamboa Ruelas | E3: ='PORTADA Y DATOS'!A6 -> Dirección | F3: ='PORTADA Y DATOS'!B6 -> Altata, Navolato, Sinaloa. | J3: =A1 -> NÚMEROS GENERADORES
A4: ='PORTADA Y DATOS'!A5 -> Obra | B4: ='PORTADA Y DATOS'!B5 -> Casa Altata | E4: ='PORTADA Y DATOS'!A4 -> Dependencia/Contratante/Cliente | H4: Logotipo | J4: 4
J5: Periodo
A6: ='PORTADA Y DATOS'!A10 -> Tipo de contrato | C6: Partida | E6: Hule negro en CT-1 y Losa | I6: HOJA: 1 | J6: De: 11/10/2021 | K6: Al: 16/10/2021
A7: ='PORTADA Y DATOS'!B10 -> Precio Unitario | I7: DE: 1 | J7: ='PORTADA Y DATOS'!A9 -> Fecha de inicio | K7: ='PORTADA Y DATOS'!B9 -> Sin definir por contratista
A8: CLAVE | B8: CONCEPTO | C8: L O C A L I Z A C I O N | F8: LARGO | G8: ANCHO | H8: ALTO | I8: PZAS | J8: UNIDAD | K8: TOTAL
C9: EJE | D9: TRAMO
A10: Responsable de la empresa | F10: ='PORTADA Y DATOS'!B11 -> Definido por parte contratante
A11: CIM_IMP_CIM_02 | B11: Suministro y colocación de hule negro en CT-1 y Losa grado industrial en cimentación. Incluye material y mano de obra. | C11: A-G | D11: 1 | E11: 8 | J11: m2 | K11: 66.42
C12: A-G | D12: 1 | E12: 8 | K12: 23.89
D13: Nota: | E13: Se toma el valor como plataforma completa, por lo que el desgloce por ejes no se indica. Se incluye la colcoación de hule en CT-1 | K13: =F13*H13 -> 0
K14: =F14*H14 -> 0
K15: =F15*H15 -> 0
K16: =F16*H16 -> 0
K17: =F17*H17 -> 0
K18: =F18*H18 -> 0
K19: =F19*H19 -> 0
K20: =F20*H20 -> 0
K21: =F21*H21 -> 0
K22: =F22*H22 -> 0
K23: =F23*H23 -> 0
K24: =F24*H24 -> 0
K25: =F25*H25 -> 0
... K37: =F37*H37 -> 0
I39: Total | J39: =J11 -> m2 | K39: =SUM(K11:K38) -> 90.31
A45: Elaboró | D45: Revisó | I45: Vo. Bo.
A46: ='PORTADA Y DATOS'!A11 -> Supervisor | D46: ='PORTADA Y DATOS'!A4 -> Dependencia/Contratante/Cliente | I46: ='PORTADA Y DATOS'!A7 -> Contratista
A47: ='PORTADA Y DATOS'!B11 -> Definido por parte contratante | D47: ='PORTADA Y DATOS'!C4 -> Luis Alberto Gamboa Ruelas | I47: ='PORTADA Y DATOS'!B7 -> Luis Alberto Gamboa Ruelas

Sheet CIM_IMP_CIM_02 (2)
A1: NÚMEROS GENERADORES
A3: ='PORTADA Y DATOS'!A7 -> Contratista | B3: ='PORTADA Y DATOS'!B7 -> Luis Alberto Gamboa Ruelas | E3: ='PORTADA Y DATOS'!A6 -> Dirección | F3: ='PORTADA Y DATOS'!B6 -> Altata, Navolato, Sinaloa. | J3: =A1 -> NÚMEROS GENERADORES
A4: ='PORTADA Y DATOS'!A5 -> Obra | B4: ='PORTADA Y DATOS'!B5 -> Casa Altata | E4: ='PORTADA Y DATOS'!A4 -> Dependencia/Contratante/Cliente | H4: Logotipo | J4: 4
J5: Periodo
A6: ='PORTADA Y DATOS'!A10 -> Tipo de contrato | C6: Partida | E6: Hule negro en ZC-1 | I6: HOJA: 1 | J6: De: 11/10/2021 | K6: Al: 16/10/2021
A7: ='PORTADA Y DATOS'!B10 -> Precio Unitario | I7: DE: 1 | J7: ='PORTADA Y DATOS'!A9 -> Fecha de inicio | K7: ='PORTADA Y DATOS'!B9 -> Sin definir por contratista
A8: CLAVE | B8: CONCEPTO | C8: L O C A L I Z A C I O N | F8: LARGO | G8: ANCHO | H8: ALTO | I8: PZAS | J8: UNIDAD | K8: TOTAL
C9: EJE | D9: TRAMO
A10: Responsable de la empresa | F10: ='PORTADA Y DATOS'!B11 -> Definido por parte contratante
A11: CIM_IMP_CIM_02 | B11: Suministro y colocación de hule negro en ZC-1 grado industrial en cimentación. Incluye material y mano de obra. | C11: A | D11: 1 | E11: 3 | F11: 2.32 | G11: 0.75 | J11: mL | K11: =(F11*G11) -> 1.74
C12: 1 | D12: A | E12: E | F12: 4.92 | G12: 0.75 | K12: =(F12*G12) -> 3.69
K13: =F13*H13 -> 0
K14: =F14*H14 -> 0
K15: =F15*H15 -> 0
K16: =F16*H16 -> 0
K17: =F17*H17 -> 0
K18: =F18*H18 -> 0
K19: =F19*H19 -> 0
K20: =F20*H20 -> 0
K21: =F21*H21 -> 0
K22: =F22*H22 -> 0
K23: =F23*H23 -> 0
K24: =F24*H24 -> 0
... K37: =F37*H37 -> 0
I39: Total | J39: =J11 -> mL | K39: =SUM(K11:K38) -> 5.43
A45: Elaboró | D45: Revisó | I45: Vo. Bo.
A46: ='PORTADA Y DATOS'!A11 -> Supervisor | D46: ='PORTADA Y DATOS'!A4 -> Dependencia/Contratante/Cliente | I46: ='PORTADA Y DATOS'!A7 -> Contratista
A47: ='PORTADA Y DATOS'!B11 -> Definido por parte contratante | D47: ='PORTADA Y DATOS'!C4 -> Luis Alberto Gamboa Ruelas | I47: ='PORTADA Y DATOS'!B7 -> Luis Alberto Gamboa Ruelas

Sheet CIM_HDA_ARM_CT-1
A1: NÚMEROS GENERADORES ACERO
A3: ='PORTADA Y DATOS'!A7 -> Contratista | B3: ='PORTADA Y DATOS'!B7 -> Luis Alberto Gamboa Ruelas | E3: ='PORTADA Y DATOS'!A6 -> Dirección | F3: ='PORTADA Y DATOS'!B6 -> Altata, Navolato, Sinaloa. | J3: =A1 -> NÚMEROS GENERADORES ACERO
A4: ='PORTADA Y DATOS'!A5 -> Obra | B4: ='PORTADA Y DATOS'!B5 -> Casa Altata | E4: ='PORTADA Y DATOS'!A4 -> Dependencia/Contratante/Cliente | H4: Logotipo | J4: 4
J5: Periodo
A6: ='PORTADA Y DATOS'!A10 -> Tipo de contrato | C6: Partida | E6: Acero refuerzo en CT-1 | I6: HOJA: 1 | J6: De: 11/10/2021 | K6: Al: 16/10/2021
A7: ='PORTADA Y DATOS'!B10 -> Precio Unitario | I7: DE: 1 | J7: ='PORTADA Y DATOS'!A9 -> Fecha de inicio | K7: ='PORTADA Y DATOS'!B9 -> Sin definir por contratista
A8: CLAVE | B8: CONCEPTO | C8: L O C A L I Z A C I O N | F8: LARGO | G8: ANCHO | H8: ALTO | I8: PZAS | J8: UNIDAD | K8: TOTAL
C9: EJE | D9: TRAMO
A10: Responsable de la empresa | F10: ='PORTADA Y DATOS'!B11 -> Definido por parte contratante
A11: CIM_HDA_ARM_CT-1 | B11: Habilitación de acero en CT-1 con armex 15x30-4. Incluye mano de obra, material y lo necesario para su correcta ejecución. | C11: A | D11: 3 | E11: 8 | F11: 8.38 | J11: mL | K11: =(F11) -> 8.38
C12: B | D12: 3 | E12: 4 | F12: 1 | K12: =(F12) -> 1
C13: C | D13: 7 | E13: 8 | F13: 0.65 | K13: =(F13) -> 0.65
C14: D | D14: 2 | E14: 5 | F14: 3.33 | K14: =(F14) -> 3.33
C15: D | D15: 6 | E15: 7 | F15: 3.15 | K15: =(F15) -> 3.15
C16: E | D16: 1 | E16: 2 | F16: 1.88 | K16: =(F16) -> 1.88
C17: F | D17: 5 | E17: 6 | F17: 1.95 | K17: =(F17) -> 1.95
C18: G | D18: 1 | E18: 7 | F18: 10.25 | K18: =(F18) -> 10.25
C19: 1 | D19: E | E19: G | F19: 2.59 | K19: =(F19) -> 2.59
C20: 2 | D20: D | E20: G | F20: 3.3 | K20: =(F20) -> 3.3
C21: 3 | D21: A | E21: B | F21: 2.75 | K21: =(F21) -> 2.75
C22: 4 | D22: B | E22: D | F22: 1.85 | K22: =(F22) -> 1.85
C23: 5 | D23: A | E23: G | F23: 7.5 | K23: =(F23) -> 7.5
C24: 6 | D24: A | E24: G | F24: 7.5 | K24: =(F24) -> 7.5
C25: 7 | D25: C | E25: G | F25: 3.9 | K25: =(F25) -> 3.9
C26: 8 | D26: A | E26: C | F26: 3.8 | K26: =(F26) -> 3.8
K27: =(F27) -> 0
K28: =(F28) -> 0
K29: =(F29) -> 0
K30: =(F30) -> 0
K31: =(F31) -> 0
K32: =(F32) -> 0
K33: =(F33) -> 0
K34: =(F34) -> 0
K35: =(F35) -> 0
K36: =(F36) -> 0
K37: =(F37) -> 0
I39: Total | J39: =J11 -> mL | K39: =SUM(K11:K38) -> 63.78
A45: Elaboró | D45: Revisó | I45: Vo. Bo.
A46: ='PORTADA Y DATOS'!A11 -> Supervisor | D46: ='PORTADA Y DATOS'!A4 -> Dependencia/Contratante/Cliente | I46: ='PORTADA Y DATOS'!A7 -> Contratista
A47: ='PORTADA Y DATOS'!B11 -> Definido por parte contratante | D47: ='PORTADA Y DATOS'!C4 -> Luis Alberto Gamboa Ruelas | I47: ='PORTADA Y DATOS'!B7 -> Luis Alberto Gamboa Ruelas

Sheet CIM_HDA_VRS-38
A1: NÚMEROS GENERADORES ACERO
A3: ='PORTADA Y DATOS'!A7 -> Contratista | B3: ='PORTADA Y DATOS'!B7 -> Luis Alberto Gamboa Ruelas | E3: ='PORTADA Y DATOS'!A6 -> Dirección | F3: ='PORTADA Y DATOS'!B6 -> Altata, Navolato, Sinaloa. | J3: =A1 -> NÚMEROS GENERADORES ACERO
A4: ='PORTADA Y DATOS'!A5 -> Obra | B4: ='PORTADA Y DATOS'!B5 -> Casa Altata | E4: ='PORTADA Y DATOS'!A4 -> Dependencia/Contratante/Cliente | H4: Logotipo | J4: 4
J5: Periodo
A6: ='PORTADA Y DATOS'!A10 -> Tipo de contrato | C6: Partida | E6: CIM_HDA_VRS-38 | I6: HOJA: 1 | J6: De: 11/10/2021 | K6: Al: 16/10/2021
A7: ='PORTADA Y DATOS'!B10 -> Precio Unitario | I7: DE: 1 | J7: ='PORTADA Y DATOS'!A9 -> Fecha de inicio | K7: ='PORTADA Y DATOS'!B9 -> Sin definir por contratista
A8: CLAVE | B8: CONCEPTO | C8: L O C A L I Z A C I O N | F8: LARGO | G8: KG*ML | H8: Ø | I8: PZAS | J8: UNIDAD | K8: TOTAL
C9: EJE | D9: TRAMO
A10: Responsable de la empresa | F10: ='PORTADA Y DATOS'!B11 -> Definido por parte contratante
A11: CIM_HDA_ARM_CT-1 | B11: Habilitación de acero de refuerzo en CT-1 con vrs #3. Incluye mano de obra, material y lo necesario para su correcta ejecución. | C11: A | D11: 3 | E11: 8 | F11: 8.38 | G11: 0.557 | H11: 0.375 | I11: 4 | J11: kg | K11: =F11*G11*I11 -> 18.67064
C12: B | D12: 3 | E12: 4 | F12: 1 | G12: 0.557 | H12: 0.375 | I12: 4 | K12: =F12*G12*I12 -> 2.228
C13: C | D13: 7 | E13: 8 | F13: 0.65 | G13: 0.557 | H13: 0.375 | I13: 4 | K13: =F13*G13*I13 -> 1.4482
C14: D | D14: 2 | E14: 5 | F14: 3.33 | G14: 0.557 | H14: 0.375 | I14: 4 | K14: =F14*G14*I14 -> 7.41924
C15: D | D15: 6 | E15: 7 | F15: 3.15 | G15: 0.557 | H15: 0.375 | I15: 4 | K15: =F15*G15*I15 -> 7.0182
C16: E | D16: 1 | E16: 2 | F16: 1.88 | G16: 0.557 | H16: 0.375 | I16: 4 | K16: =F16*G16*I16 -> 4.18864
C17: F | D17: 5 | E17: 6 | F17: 1.95 | G17: 0.557 | H17: 0.375 | I17: 4 | K17: =F17*G17*I17 -> 4.3446
C18: G | D18: 1 | E18: 7 | F18: 10.25 | G18: 0.557 | H18: 0.375 | I18: 4 | K18: =F18*G18*I18 -> 22.837
C19: 1 | D19: E | E19: G | F19: 2.59 | G19: 0.557 | H19: 0.375 | I19: 4 | K19: =F19*G19*I19 -> 5.77052
C20: 2 | D20: D | E20: G | F20: 3.3 | G20: 0.557 | H20: 0.375 | I20: 4 | K20: =F20*G20*I20 -> 7.3524
C21: 3 | D21: A | E21: B | F21: 2.75 | G21: 0.557 | H21: 0.375 | I21: 4 | K21: =F21*G21*I21 -> 6.127
C22: 4 | D22: B | E22: D | F22: 1.85 | G22: 0.557 | H22: 0.375 | I22: 4 | K22: =F22*G22*I22 -> 4.1218
C23: 5 | D23: A | E23: G | F23: 7.5 | G23: 0.557 | H23: 0.375 | I23: 4 | K23: =F23*G23*I23 -> 16.71
C24: 6 | D24: A | E24: G | F24: 7.5 | G24: 0.557 | H24: 0.375 | I24: 4 | K24: =F24*G24*I24 -> 16.71
C25: 7 | D25: C | E25: G | F25: 3.9 | G25: 0.557 | H25: 0.375 | I25: 4 | K25: =F25*G25*I25 -> 8.6892
C26: 8 | D26: A | E26: C | F26: 3.8 | G26: 0.557 | H26: 0.375 | I26: 4 | K26: =F26*G26*I26 -> 8.4664
K27: =F27*G27*I27 -> 0
K28: =F28*G28*I28 -> 0
K29: =F29*G29*I29 -> 0
K30: =F30*G30*I30 -> 0
K31: =F31*G31*I31 -> 0
K32: =F32*G32*I32 -> 0
K33: =F33*G33*I33 -> 0
K34: =F34*G34*I34 -> 0
K35: =F35*G35*I35 -> 0
K36: =F36*G36*I36 -> 0
K37: =F37*G37*I37 -> 0
I39: Total | J39: =J11 -> kg | K39: =SUM(K11:K38) -> 142.10184
A45: Elaboró | D45: Revisó | I45: Vo. Bo.
A46: ='PORTADA Y DATOS'!A11 -> Supervisor | D46: ='PORTADA Y DATOS'!A4 -> Dependencia/Contratante/Cliente | I46: ='PORTADA Y DATOS'!A7 -> Contratista
A47: ='PORTADA Y DATOS'!B11 -> Definido por parte contratante | D47: ='PORTADA Y DATOS'!C4 -> Luis Alberto Gamboa Ruelas | I47: ='PORTADA Y DATOS'!B7 -> Luis Alberto Gamboa Ruelas

Sheet CIM_HDA_VRS-38_BST
A1: NÚMEROS GENERADORES ACERO
A3: ='PORTADA Y DATOS'!A7 -> Contratista | B3: ='PORTADA Y DATOS'!B7 -> Luis Alberto Gamboa Ruelas | E3: ='PORTADA Y DATOS'!A6 -> Dirección | F3: ='PORTADA Y DATOS'!B6 -> Altata, Navolato, Sinaloa. | J3: =A1 -> NÚMEROS GENERADORES ACERO
A4: ='PORTADA Y DATOS'!A5 -> Obra | B4: ='PORTADA Y DATOS'!B5 -> Casa Altata | E4: ='PORTADA Y DATOS'!A4 -> Dependencia/Contratante/Cliente | H4: Logotipo | J4: 4
J5: Periodo
A6: ='PORTADA Y DATOS'!A10 -> Tipo de contrato | C6: Partida | E6: Habilitado de acero en bastones de losa de cimentación | I6: HOJA: 1 | J6: De: 11/10/2021 | K6: Al: 16/10/2021
A7: ='PORTADA Y DATOS'!B10 -> Precio Unitario | I7: DE: 1 | J7: ='PORTADA Y DATOS'!A9 -> Fecha de inicio | K7: ='PORTADA Y DATOS'!B9 -> Sin definir por contratista
A8: CLAVE | B8: CONCEPTO | C8: L O C A L I Z A C I O N | F8: LARGO | G8: KG*ML | H8: Ø | I8: PZAS | J8: UNIDAD | K8: TOTAL
C9: EJE | D9: TRAMO
A10: Responsable de la empresa | F10: ='PORTADA Y DATOS'!B11 -> Definido por parte contratante
A11: CIM_HDA_VRS-38_BST | B11: Habilitación de acero para bastones y vrs. longitudinales para losa de cimentación de acuerdo a detalle proporcionado por el cliente. Incluye material y desperdicio. No incluye mano de obra. | C11: A | D11: 3 | E11: 8 | F11: 0.95 | G11: 0.557 | H11: 0.375 | I11: 53 | J11: kg | K11: =F11*G11*I11 -> 28.04495
C12: B | D12: 3 | E12: 4 | F12: 0.95 | G12: 0.557 | H12: 0.375 | I12: 6 | K12: =F12*G12*I12 -> 3.1749
C13: C | D13: 7 | E13: 8 | F13: 0.95 | G13: 0.557 | H13: 0.375 | I13: 4 | K13: =F13*G13*I13 -> 2.1166
C14: D | D14: 2 | E14: 5 | F14: 1.35 | G14: 0.557 | H14: 0.375 | I14: 12 | K14: =F14*G14*I14 -> 9.0234
C15: D | D15: 6 | E15: 7 | F15: 1.35 | G15: 0.557 | H15: 0.375 | I15: 21 | K15: =F15*G15*I15 -> 15.79095
C16: E | D16: 1 | E16: 2 | F16: 0.95 | G16: 0.557 | H16: 0.375 | I16: 13 | K16: =F16*G16*I16 -> 6.87895
C17: F | D17: 5 | E17: 6 | F17: 1.35 | G17: 0.557 | H17: 0.375 | I17: 13 | K17: =F17*G17*I17 -> 9.77535
C18: G | D18: 1 | E18: 7 | F18: 0.95 | G18: 0.557 | H18: 0.375 | I18: 69 | K18: =F18*G18*I18 -> 36.51135
C19: 1 | D19: E | E19: G | F19: 0.95 | G19: 0.557 | H19: 0.375 | I19: 16 | K19: =F19*G19*I19 -> 8.4664
C20: 2 | D20: E | E20: G | F20: 1.35 | G20: 0.557 | H20: 0.375 | I20: 16 | K20: =F20*G20*I20 -> 12.0312
C21: 3 | D21: A | E21: B | F21: 0.95 | G21: 0.557 | H21: 0.375 | I21: 17 | K21: =F21*G21*I21 -> 8.99555
C22: 4 | D22: B | E22: D | F22: 0.95 | G22: 0.557 | H22: 0.375 | I22: 11 | K22: =F22*G22*I22 -> 5.82065
C23: 5 | D23: D | E23: G | F23: 1.35 | G23: 0.557 | H23: 0.375 | I23: 20 | K23: =F23*G23*I23 -> 15.039
C24: 6 | D24: D | E24: G | F24: 1.35 | G24: 0.557 | H24: 0.375 | I24: 20 | K24: =F24*G24*I24 -> 15.039
C25: 7 | D25: C | E25: G | F25: 0.95 | G25: 0.557 | H25: 0.375 | I25: 24 | K25: =F25*G25*I25 -> 12.6996
C26: 8 | D26: A | E26: C | F26: 0.95 | G26: 0.557 | H26: 0.375 | I26: 24 | K26: =F26*G26*I26 -> 12.6996
K27: =F27*G27*I27 -> 0
E28: Nota: | F28: Se incluye un 6% de alambre recocido por kg | K28: =F28*G28*I28 -> #VALUE!
K29: =F29*G29*I29 -> 0
K30: =F30*G30*I30 -> 0
K31: =F31*G31*I31 -> 0
K32: =F32*G32*I32 -> 0
K33: =F33*G33*I33 -> 0
K34: =F34*G34*I34 -> 0
K35: =F35*G35*I35 -> 0
K36: =F36*G36*I36 -> 0
K37: =F37*G37*I37 -> 0
I39: Total | J39: =J11 -> kg | K39: =SUM(K11:K38) -> #VALUE!
A45: Elaboró | D45: Revisó | I45: Vo. Bo.
A46: ='PORTADA Y DATOS'!A11 -> Supervisor | D46: ='PORTADA Y DATOS'!A4 -> Dependencia/Contratante/Cliente | I46: ='PORTADA Y DATOS'!A7 -> Contratista
A47: ='PORTADA Y DATOS'!B11 -> Definido por parte contratante | D47: ='PORTADA Y DATOS'!C4 -> Luis Alberto Gamboa Ruelas | I47: ='PORTADA Y DATOS'!B7 -> Luis Alberto Gamboa Ruelas

Sheet CIM_HDA_ZC-1
A1: NÚMEROS GENERADORES ACERO
A3: ='PORTADA Y DATOS'!A7 -> Contratista | B3: ='PORTADA Y DATOS'!B7 -> Luis Alberto Gamboa Ruelas | E3: ='PORTADA Y DATOS'!A6 -> Dirección | F3: ='PORTADA Y DATOS'!B6 -> Altata, Navolato, Sinaloa. | K3: =A1 -> NÚMEROS GENERADORES ACERO
A4: ='PORTADA Y DATOS'!A5 -> Obra | B4: ='PORTADA Y DATOS'!B5 -> Casa Altata | E4: ='PORTADA Y DATOS'!A4 -> Dependencia/Contratante/Cliente | I4: Logotipo | K4: 4
K5: Periodo
A6: ='PORTADA Y DATOS'!A10 -> Tipo de contrato | C6: Partida | E6: Habilitado de acero en ZC-1 | J6: HOJA: 1 | K6: De: 11/10/2021 | L6: Al: 16/10/2021
A7: ='PORTADA Y DATOS'!B10 -> Precio Unitario | J7: DE: 1 | K7: ='PORTADA Y DATOS'!A9 -> Fecha de inicio | L7: ='PORTADA Y DATOS'!B9 -> Sin definir por contratista
A8: CLAVE | B8: CONCEPTO | C8: L O C A L I Z A C I O N | F8: AT (mL) | G8: AL (pza) | H8: KG*ML | I8: Ø | K8: UNIDAD | L8: TOTAL
C9: EJE | D9: TRAMO
A10: Responsable de la empresa | F10: ='PORTADA Y DATOS'!B11 -> Definido por parte contratante
A11: CIM_HDA_VRS-38_BST | B11: Habilitado de acero en ZC-1 con parrilla sencilla armada con 3 vrs #3 AT y vrs #3 @25cm en AL. Incluye material, mano de obra y desperdicio. | C11: A | D11: 1 | E11: 3 | F11: 2.32 | G11: 3 | H11: 0.56 | I11: 0.375 | K11: kg | L11: =(F11/0.25)+(F11*G11)*H11 -> 13.1776
C12: 1 | D12: A | E12: E | F12: 4.92 | G12: 3 | H12: 0.557 | I12: 0.375 | L12: =(F12/0.25)+(F12*G12)*H12 -> 27.90132
E28: Nota: | F28: Se incluye un 6% de alambre recocido por kg
J39: Total | K39: =K11 -> kg | L39: =SUM(L11:L38) -> 41.07892
A45: Elaboró | D45: Revisó | J45: Vo. Bo.
A46: ='PORTADA Y DATOS'!A11 -> Supervisor | D46: ='PORTADA Y DATOS'!A4 -> Dependencia/Contratante/Cliente | J46: ='PORTADA Y DATOS'!A7 -> Contratista
A47: ='PORTADA Y DATOS'!B11 -> Definido por parte contratante | D47: ='PORTADA Y DATOS'!C4 -> Luis Alberto Gamboa Ruelas | J47: ='PORTADA Y DATOS'!B7 -> Luis Alberto Gamboa Ruelas

Sheet LC_HDA_MES_01
A1: NÚMEROS GENERADORES ACERO
A3: ='PORTADA Y DATOS'!A7 -> Contratista | B3: ='PORTADA Y DATOS'!B7 -> Luis Alberto Gamboa Ruelas | E3: ='PORTADA Y DATOS'!A6 -> Dirección | F3: ='PORTADA Y DATOS'!B6 -> Altata, Navolato, Sinaloa. | J3: =A1 -> NÚMEROS GENERADORES ACERO
A4: ='PORTADA Y DATOS'!A5 -> Obra | B4: ='PORTADA Y DATOS'!B5 -> Casa Altata | E4: ='PORTADA Y DATOS'!A4 -> Dependencia/Contratante/Cliente | H4: Logotipo | J4: 4
J5: Periodo
A6: ='PORTADA Y DATOS'!A10 -> Tipo de contrato | C6: Partida | E6: Acero refuerzo en CT-1 | I6: HOJA: 1 | J6: De: 11/10/2021 | K6: Al: 16/10/2021
A7: ='PORTADA Y DATOS'!B10 -> Precio Unitario | I7: DE: 1 | J7: ='PORTADA Y DATOS'!A9 -> Fecha de inicio | K7: ='PORTADA Y DATOS'!B9 -> Sin definir por contratista
A8: CLAVE | B8: CONCEPTO | C8: L O C A L I Z A C I O N | F8: LARGO | G8: ANCHO | H8: ALTO | I8: PZAS | J8: UNIDAD | K8: TOTAL
C9: EJE | D9: TRAMO
A10: Responsable de la empresa | F10: ='PORTADA Y DATOS'!B11 -> Definido por parte contratante
A11: LC_HDA_MES_01 | B11: Suministro de malla electrosoldada 6x6, 8/8. Incluye material. No incluye mano de obra. | C11: A-G | D11: 1 | E11: 8 | J11: m2 | K11: 66.42
C12: A-G | D12: 1 | E12: 8 | K12: 23.89
D13: Nota: | E13: Se toma el valor como plataforma completa, por lo que el desgloce por ejes no se indica. Se incluye la colcoación de hule en CT-1
I39: Total | J39: =J11 -> m2 | K39: =SUM(K11:K38) -> 90.31
A45: Elaboró | D45: Revisó | I45: Vo. Bo.
A46: ='PORTADA Y DATOS'!A11 -> Supervisor | D46: ='PORTADA Y DATOS'!A4 -> Dependencia/Contratante/Cliente | I46: ='PORTADA Y DATOS'!A7 -> Contratista
A47: ='PORTADA Y DATOS'!B11 -> Definido por parte contratante | D47: ='PORTADA Y DATOS'!C4 -> Luis Alberto Gamboa Ruelas | I47: ='PORTADA Y DATOS'!B7 -> Luis Alberto Gamboa Ruelas

Sheet CIM_HDC_01
A1: NÚMEROS GENERADORES ACERO
A3: ='PORTADA Y DATOS'!A7 -> Contratista | B3: ='PORTADA Y DATOS'!B7 -> Luis Alberto Gamboa Ruelas | E3: ='PORTADA Y DATOS'!A6 -> Dirección | F3: ='PORTADA Y DATOS'!B6 -> Altata, Navolato, Sinaloa. | J3: =A1 -> NÚMEROS GENERADORES ACERO
A4: ='PORTADA Y DATOS'!A5 -> Obra | B4: ='PORTADA Y DATOS'!B5 -> Casa Altata | E4: ='PORTADA Y DATOS'!A4 -> Dependencia/Contratante/Cliente | H4: Logotipo | J4: 4
J5: Periodo
A6: ='PORTADA Y DATOS'!A10 -> Tipo de contrato | C6: Partida | E6: Cimbra perimetral en losa de cimentación | I6: HOJA: 1 | J6: De: 11/10/2021 | K6: Al: 16/10/2021
A7: ='PORTADA Y DATOS'!B10 -> Precio Unitario | I7: DE: 1 | J7: ='PORTADA Y DATOS'!A9 -> Fecha de inicio | K7: ='PORTADA Y DATOS'!B9 -> Sin definir por contratista
A8: CLAVE | B8: CONCEPTO | C8: L O C A L I Z A C I O N | F8: LARGO | G8: ANCHO | H8: ALTO | I8: PZAS | J8: UNIDAD | K8: TOTAL
C9: EJE | D9: TRAMO
A10: Responsable de la empresa | F10: ='PORTADA Y DATOS'!B11 -> Definido por parte contratante
A11: CIM_HDC_01 | B11: Habilitado de cimbra para perimetral de losa de cimentación con triplay de 3/4" y barrotes 3x3x8' como puntal @50cm. Incluye material y lo necesario para su correcta ejecución. | C11: A | D11: 3 | E11: 8 | F11: 8.38 | J11: mL | K11: =F11 -> 8.38
C12: B | D12: 3 | E12: 4 | F12: 0.76 | K12: =F12 -> 0.76
C13: D | D13: 2 | E13: 4 | F13: 1.32 | K13: =F13 -> 1.32
C14: E | D14: 1 | E14: 2 | F14: 1.8 | K14: =F14 -> 1.8
C15: G | D15: 1 | E15: 7 | F15: 10.25 | K15: =F15 -> 10.25
C16: 1 | D16: E | E16: G | F16: 2.58 | K16: =F16 -> 2.58
C17: 2 | D17: D | E17: E | F17: 0.72 | K17: =F17 -> 0.72
C18: 3 | D18: A | E18: B | F18: 2.75 | K18: =F18 -> 2.75
C19: 4 | D19: B | E19: D | F19: 1.45 | K19: =F19 -> 1.45
C20: 7 | D20: C | E20: G | F20: 3.68 | K20: =F20 -> 3.68
C21: 8 | D21: A | E21: C | F21: 3.8 | K21: =F21 -> 3.8
I39: Total | J39: =J11 -> mL | K39: =SUM(K11:K38) -> 37.49
A45: Elaboró | D45: Revisó | I45: Vo. Bo.
A46: ='PORTADA Y DATOS'!A11 -> Supervisor | D46: ='PORTADA Y DATOS'!A4 -> Dependencia/Contratante/Cliente | I46: ='PORTADA Y DATOS'!A7 -> Contratista
A47: ='PORTADA Y DATOS'!B11 -> Definido por parte contratante | D47: ='PORTADA Y DATOS'!C4 -> Luis Alberto Gamboa Ruelas | I47: ='PORTADA Y DATOS'!B7 -> Luis Alberto Gamboa Ruelas

Sheet CIM_CPC_200_01
A1: NÚMEROS GENERADORES ACERO
A3: ='PORTADA Y DATOS'!A7 -> Contratista | B3: ='PORTADA Y DATOS'!B7 -> Luis Alberto Gamboa Ruelas | E3: ='PORTADA Y DATOS'!A6 -> Dirección | F3: ='PORTADA Y DATOS'!B6 -> Altata, Navolato, Sinaloa. | J3: =A1 -> NÚMEROS GENERADORES ACERO
A4: ='PORTADA Y DATOS'!A5 -> Obra | B4: ='PORTADA Y DATOS'!B5 -> Casa Altata | E4: ='PORTADA Y DATOS'!A4 -> Dependencia/Contratante/Cliente | H4: Logotipo | J4: 4
J5: Periodo
A6: ='PORTADA Y DATOS'!A10 -> Tipo de contrato | C6: Partida | E6: Cimbra perimetral en losa de cimentación | I6: HOJA: 1 | J6: De: 11/10/2021 | K6: Al: 16/10/2021
A7: ='PORTADA Y DATOS'!B10 -> Precio Unitario | I7: DE: 1 | J7: ='PORTADA Y DATOS'!A9 -> Fecha de inicio | K7: ='PORTADA Y DATOS'!B9 -> Sin definir por contratista
A8: CLAVE | B8: CONCEPTO | C8: L O C A L I Z A C I O N | F8: LARGO | G8: ANCHO | H8: ALTO | I8: PZAS | J8: UNIDAD | K8: TOTAL
C9: EJE | D9: TRAMO
A10: Responsable de la empresa | F10: ='PORTADA Y DATOS'!B11 -> Definido por parte contratante
A11: CIM_CPC_200_01 | B11: Suministro de concreto premezclado en -0.30m a -0.12m f'c:200kg/cm2 rev. 8 a 10cm. Tamaño máximo del agregado a 3/4". Incluye todo lo necesario. | C11: A | D11: 3 | E11: 8 | F11: 8.38 | G11: 0.2 | H11: 0.18 | J11: m3 | K11: =F11*G11*H11 -> 0.30168
C12: B | D12: 3 | E12: 4 | F12: 1 | G12: 0.2 | H12: 0.18 | K12: =F12*G12*H12 -> 0.036
C13: C | D13: 7 | E13: 8 | F13: 0.65 | G13: 0.2 | H13: 0.18 | K13: =F13*G13*H13 -> 0.0234
C14: D | D14: 2 | E14: 5 | F14: 3.33 | G14: 0.2 | H14: 0.18 | K14: =F14*G14*H14 -> 0.11988
C15: D | D15: 6 | E15: 7 | F15: 3.15 | G15: 0.2 | H15: 0.18 | K15: =F15*G15*H15 -> 0.1134
C16: E | D16: 1 | E16: 2 | F16: 1.88 | G16: 0.2 | H16: 0.18 | K16: =F16*G16*H16 -> 0.06768
C17: F | D17: 5 | E17: 6 | F17: 1.95 | G17: 0.2 | H17: 0.18 | K17: =F17*G17*H17 -> 0.0702
C18: G | D18: 1 | E18: 7 | F18: 10.25 | G18: 0.2 | H18: 0.18 | K18: =F18*G18*H18 -> 0.369
C19: 1 | D19: E | E19: G | F19: 2.59 | G19: 0.2 | H19: 0.18 | K19: =F19*G19*H19 -> 0.09324
C20: 2 | D20: D | E20: G | F20: 3.3 | G20: 0.2 | H20: 0.18 | K20: =F20*G20*H20 -> 0.1188
C21: 3 | D21: A | E21: B | F21: 2.75 | G21: 0.2 | H21: 0.18 | K21: =F21*G21*H21 -> 0.099
C22: 4 | D22: B | E22: D | F22: 1.85 | G22: 0.2 | H22: 0.18 | K22: =F22*G22*H22 -> 0.0666
C23: 5 | D23: A | E23: G | F23: 7.5 | G23: 0.2 | H23: 0.18 | K23: =F23*G23*H23 -> 0.27
C24: 6 | D24: A | E24: G | F24: 7.5 | G24: 0.2 | H24: 0.18 | K24: =F24*G24*H24 -> 0.27
C25: 7 | D25: C | E25: G | F25: 3.9 | G25: 0.2 | H25: 0.18 | K25: =F25*G25*H25 -> 0.1404
C26: 8 | D26: A | E26: C | F26: 3.8 | G26: 0.2 | H26: 0.18 | K26: =F26*G26*H26 -> 0.1368
I39: Total | J39: =J11 -> m3 | K39: =SUM(K11:K38) -> 2.29608
A45: Elaboró | D45: Revisó | I45: Vo. Bo.
A46: ='PORTADA Y DATOS'!A11 -> Supervisor | D46: ='PORTADA Y DATOS'!A4 -> Dependencia/Contratante/Cliente | I46: ='PORTADA Y DATOS'!A7 -> Contratista
A47: ='PORTADA Y DATOS'!B11 -> Definido por parte contratante | D47: ='PORTADA Y DATOS'!C4 -> Luis Alberto Gamboa Ruelas | I47: ='PORTADA Y DATOS'!B7 -> Luis Alberto Gamboa Ruelas

Sheet CIM_CPC_200_02
A1: NÚMEROS GENERADORES ACERO
A3: ='PORTADA Y DATOS'!A7 -> Contratista | B3: ='PORTADA Y DATOS'!B7 -> Luis Alberto Gamboa Ruelas | E3: ='PORTADA Y DATOS'!A6 -> Dirección | F3: ='PORTADA Y DATOS'!B6 -> Altata, Navolato, Sinaloa. | J3: =A1 -> NÚMEROS GENERADORES ACERO
A4: ='PORTADA Y DATOS'!A5 -> Obra | B4: ='PORTADA Y DATOS'!B5 -> Casa Altata | E4: ='PORTADA Y DATOS'!A4 -> Dependencia/Contratante/Cliente | H4: Logotipo | J4: 4
J5: Periodo
A6: ='PORTADA Y DATOS'!A10 -> Tipo de contrato | C6: Partida | E6: Cimbra perimetral en losa de cimentación | I6: HOJA: 1 | J6: De: 11/10/2021 | K6: Al: 16/10/2021
A7: ='PORTADA Y DATOS'!B10 -> Precio Unitario | I7: DE: 1 | J7: ='PORTADA Y DATOS'!A9 -> Fecha de inicio | K7: ='PORTADA Y DATOS'!B9 -> Sin definir por contratista
A8: CLAVE | B8: CONCEPTO | C8: L O C A L I Z A C I O N | F8: LARGO | G8: ANCHO | H8: ALTO | I8: PZAS | J8: UNIDAD | K8: TOTAL
C9: EJE | D9: TRAMO
A10: Responsable de la empresa | F10: ='PORTADA Y DATOS'!B11 -> Definido por parte contratante
A11: CIM_CPC_200_02 | B11: Suministro de concreto premezclado en -0.12m a -0.08m f'c:200kg/cm2 rev. 8 a 10cm. Tamaño máximo del agregado a 3/4". Incluye todo lo necesario. | C11: A-G | D11: 1 | E11: 8 | J11: m3 | K11: =66.42*0.04 -> 2.6568
D13: Nota: | E13: Se toma el valor como plataforma completa, por lo que el desgloce por ejes no se indica.
I39: Total | J39: =J11 -> m3 | K39: =SUM(K11:K38) -> 2.6568
A45: Elaboró | D45: Revisó | I45: Vo. Bo.
A46: ='PORTADA Y DATOS'!A11 -> Supervisor | D46: ='PORTADA Y DATOS'!A4 -> Dependencia/Contratante/Cliente | I46: ='PORTADA Y DATOS'!A7 -> Contratista
A47: ='PORTADA Y DATOS'!B11 -> Definido por parte contratante | D47: ='PORTADA Y DATOS'!C4 -> Luis Alberto Gamboa Ruelas | I47: ='PORTADA Y DATOS'!B7 -> Luis Alberto Gamboa Ruelas

Sheet CIM_CPC_200_03
A1: NÚMEROS GENERADORES ACERO
A3: ='PORTADA Y DATOS'!A7 -> Contratista | B3: ='PORTADA Y DATOS'!B7 -> Luis Alberto Gamboa Ruelas | E3: ='PORTADA Y DATOS'!A6 -> Dirección | F3: ='PORTADA Y DATOS'!B6 -> Altata, Navolato, Sinaloa. | J3: =A1 -> NÚMEROS GENERADORES ACERO
A4: ='PORTADA Y DATOS'!A5 -> Obra | B4: ='PORTADA Y DATOS'!B5 -> Casa Altata | E4: ='PORTADA Y DATOS'!A4 -> Dependencia/Contratante/Cliente | H4: Logotipo | J4: 4
J5: Periodo
A6: ='PORTADA Y DATOS'!A10 -> Tipo de contrato | C6: Partida | E6: Cimbra perimetral en losa de cimentación | I6: HOJA: 1 | J6: De: 11/10/2021 | K6: Al: 16/10/2021
A7: ='PORTADA Y DATOS'!B10 -> Precio Unitario | I7: DE: 1 | J7: ='PORTADA Y DATOS'!A9 -> Fecha de inicio | K7: ='PORTADA Y DATOS'!B9 -> Sin definir por contratista
A8: CLAVE | B8: CONCEPTO | C8: L O C A L I Z A C I O N | F8: LARGO | G8: ANCHO | H8: ALTO | I8: PZAS | J8: UNIDAD | K8: TOTAL
C9: EJE | D9: TRAMO
A10: Responsable de la empresa | F10: ='PORTADA Y DATOS'!B11 -> Definido por parte contratante
A11: CIM_CPC_200_03 | B11: Suministro de concreto premezclado en -0.08m a -0.00m f'c:200kg/cm2 rev. 8 a 10cm. Tamaño máximo del agregado a 3/4". Incluye todo lo necesario. | C11: A-G | D11: 1 | E11: 8 | J11: m3 | K11: =66.42*0.08 -> 5.3136
D13: Nota: | E13: Se toma el valor como plataforma completa, por lo que el desgloce por ejes no se indica.
I39: Total | J39: =J11 -> m3 | K39: =SUM(K11:K38) -> 5.3136
A45: Elaboró | D45: Revisó | I45: Vo. Bo.
A46: ='PORTADA Y DATOS'!A11 -> Supervisor | D46: ='PORTADA Y DATOS'!A4 -> Dependencia/Contratante/Cliente | I46: ='PORTADA Y DATOS'!A7 -> Contratista
A47: ='PORTADA Y DATOS'!B11 -> Definido por parte contratante | D47: ='PORTADA Y DATOS'!C4 -> Luis Alberto Gamboa Ruelas | I47: ='PORTADA Y DATOS'!B7 -> Luis Alberto Gamboa Ruelas

Sheet CIM_MOC_01
A1: NÚMEROS GENERADORES ACERO
A3: ='PORTADA Y DATOS'!A7 -> Contratista | B3: ='PORTADA Y DATOS'!B7 -> Luis Alberto Gamboa Ruelas | E3: ='PORTADA Y DATOS'!A6 -> Dirección | F3: ='PORTADA Y DATOS'!B6 -> Altata, Navolato, Sinaloa. | J3: =A1 -> NÚMEROS GENERADORES ACERO
A4: ='PORTADA Y DATOS'!A5 -> Obra | B4: ='PORTADA Y DATOS'!B5 -> Casa Altata | E4: ='PORTADA Y DATOS'!A4 -> Dependencia/Contratante/Cliente | H4: Logotipo | J4: 4
J5: Periodo
A6: ='PORTADA Y DATOS'!A10 -> Tipo de contrato | C6: Partida | E6: Mano de obra para trabajos de cimentación | I6: HOJA: 1 | J6: De: 11/10/2021 | K6: Al: 16/10/2021
A7: ='PORTADA Y DATOS'!B10 -> Precio Unitario | I7: DE: 1 | J7: ='PORTADA Y DATOS'!A9 -> Fecha de inicio | K7: ='PORTADA Y DATOS'!B9 -> Sin definir por contratista
A8: CLAVE | B8: CONCEPTO | C8: L O C A L I Z A C I O N | F8: LARGO | G8: ANCHO | H8: ALTO | I8: PZAS | J8: UNIDAD | K8: TOTAL
C9: EJE | D9: TRAMO
A10: Responsable de la empresa | F10: ='PORTADA Y DATOS'!B11 -> Definido por parte contratante
A11: CIM_MOC_01 | B11: Mano de obra para trabajos en losa de cimentación. Incluye mano de obra. | C11: A-G | D11: 1 | E11: 8 | J11: m3 | K11: =66.42 -> 66.42
D13: Nota: | E13: Se toma el valor como plataforma completa, por lo que el desgloce por ejes no se indica.
I39: Total | J39: =J11 -> m3 | K39: =SUM(K11:K38) -> 66.42
A45: Elaboró | D45: Revisó | I45: Vo. Bo.
A46: ='PORTADA Y DATOS'!A11 -> Supervisor | D46: ='PORTADA Y DATOS'!A4 -> Dependencia/Contratante/Cliente | I46: ='PORTADA Y DATOS'!A7 -> Contratista
A47: ='PORTADA Y DATOS'!B11 -> Definido por parte contratante | D47: ='PORTADA Y DATOS'!C4 -> Luis Alberto Gamboa Ruelas | I47: ='PORTADA Y DATOS'!B7 -> Luis Alberto Gamboa Ruelas

Sheet CIM_MOC_02
A1: NÚMEROS GENERADORES ACERO
A3: ='PORTADA Y DATOS'!A7 -> Contratista | B3: ='PORTADA Y DATOS'!B7 -> Luis Alberto Gamboa Ruelas | E3: ='PORTADA Y DATOS'!A6 -> Dirección | F3: ='PORTADA Y DATOS'!B6 -> Altata, Navolato, Sinaloa. | J3: =A1 -> NÚMEROS GENERADORES ACERO
A4: ='PORTADA Y DATOS'!A5 -> Obra | B4: ='PORTADA Y DATOS'!B5 -> Casa Altata | E4: ='PORTADA Y DATOS'!A4 -> Dependencia/Contratante/Cliente | H4: Logotipo | J4: 4
J5: Periodo
A6: ='PORTADA Y DATOS'!A10 -> Tipo de contrato | C6: Partida | E6: Mano de obra para trabajos de cimentación | I6: HOJA: 1 | J6: De: 11/10/2021 | K6: Al: 16/10/2021
A7: ='PORTADA Y DATOS'!B10 -> Precio Unitario | I7: DE: 1 | J7: ='PORTADA Y DATOS'!A9 -> Fecha de inicio | K7: ='PORTADA Y DATOS'!B9 -> Sin definir por contratista
A8: CLAVE | B8: CONCEPTO | C8: L O C A L I Z A C I O N | F8: LARGO | G8: ANCHO | H8: ALTO | I8: PZAS | J8: UNIDAD | K8: TOTAL
C9: EJE | D9: TRAMO
A10: Responsable de la empresa | F10: ='PORTADA Y DATOS'!B11 -> Definido por parte contratante
A11: CIM_MOC_02 | B11: Mano de obra para trabajos en ZC-1. Incluye mano de obra. | C11: A | D11: 1 | E11: 3 | F11: 2.32 | G11: 0.75 | J11: m2 | K11: =(F11*G11) -> 1.74
C12: 1 | D12: A | E12: E | F12: 4.92 | G12: 0.75 | K12: =(F12*G12) -> 3.69
I39: Total | J39: =J11 -> m2 | K39: =SUM(K11:K38) -> 5.43
A45: Elaboró | D45: Revisó | I45: Vo. Bo.
A46: ='PORTADA Y DATOS'!A11 -> Supervisor | D46: ='PORTADA Y DATOS'!A4 -> Dependencia/Contratante/Cliente | I46: ='PORTADA Y DATOS'!A7 -> Contratista
A47: ='PORTADA Y DATOS'!B11 -> Definido por parte contratante | D47: ='PORTADA Y DATOS'!C4 -> Luis Alberto Gamboa Ruelas | I47: ='PORTADA Y DATOS'!B7 -> Luis Alberto Gamboa Ruelas

Sheet MUR_BLC_01
A1: NÚMEROS GENERADORES ACERO
A3: ='PORTADA Y DATOS'!A7 -> Contratista | B3: ='PORTADA Y DATOS'!B7 -> Luis Alberto Gamboa Ruelas | E3: ='PORTADA Y DATOS'!A6 -> Dirección | F3: ='PORTADA Y DATOS'!B6 -> Altata, Navolato, Sinaloa. | J3: =A1 -> NÚMEROS GENERADORES ACERO
A4: ='PORTADA Y DATOS'!A5 -> Obra | B4: ='PORTADA Y DATOS'!B5 -> Casa Altata | E4: ='PORTADA Y DATOS'!A4 -> Dependencia/Contratante/Cliente | H4: Logotipo | J4: 4
J5: Periodo
A6: ='PORTADA Y DATOS'!A10 -> Tipo de contrato | C6: Partida | E6: Muro de block | I6: HOJA: 1 | J6: De: 11/10/2021 | K6: Al: 16/10/2021
A7: ='PORTADA Y DATOS'!B10 -> Precio Unitario | I7: DE: 1 | J7: ='PORTADA Y DATOS'!A9 -> Fecha de inicio | K7: ='PORTADA Y DATOS'!B9 -> Sin definir por contratista
A8: CLAVE | B8: CONCEPTO | C8: L O C A L I Z A C I O N | F8: LARGO | G8: ANCHO | H8: ALTO | I8: PZAS | J8: UNIDAD | K8: TOTAL
C9: EJE | D9: TRAMO
A10: Responsable de la empresa | F10: ='PORTADA Y DATOS'!B11 -> Definido por parte contratante
A11: MUR_BLC_01 | B11: Muro de block 12x20x40 asentado con mortero/arena. 1:5, incluye: material, mano de obra y herramienta. | C11: A | D11: 1 | E11: 8 | F11: 10.7 | H11: 2.7 | J11: m2 | K11: =F11*H11 -> 28.89
C12: B | D12: 3 | E12: 4 | F12: 0.95 | H12: 2.7 | K12: =F12*H12 -> 2.565
C13: C | D13: 7 | E13: 8 | F13: 0.75 | H13: 2.7 | K13: =F13*H13 -> 2.025
C14: D | D14: 2 | E14: 5 | F14: 3.3 | H14: 2.7 | K14: =F14*H14 -> 8.91
C15: D | D15: 6 | E15: 7 | F15: 3.35 | H15: 2.7 | K15: =F15*H15 -> 9.045
C16: E | D16: 1 | E16: 2 | F16: 1.15 | H16: 2.3 | K16: =F16*H16 -> 2.645
C17: E | D17: 1 | E17: 2 | F17: 0.8 | H17: 2.7 | K17: =F17*H17 -> 2.16
C18: F | D18: 5 | E18: 6 | F18: 1.15 | H18: 2.7 | K18: =F18*H18 -> 3.105
C19: G | D19: 1 | E19: 7 | F19: 10.2 | H19: 2.7 | K19: =F19*H19 -> 27.54
C20: 1 | D20: A | E20: G | F20: 7.5 | H20: 2.7 | K20: =F20*H20 -> 20.25
C21: 2 | D21: D | E21: E | F21: 1.05 | H21: 2.3 | K21: =F21*H21 -> 2.415
C22: 2 | D22: E | E22: G | F22: 2.58 | H22: 2.7 | K22: =F22*H22 -> 6.966
C23: 3 | D23: A | E23: A' | F23: 0.93 | H23: 0.9 | K23: =F23*H23 -> 0.837
C24: 3 | D24: A' | E24: B | F24: 0.95 | H24: 2.7 | K24: =F24*H24 -> 2.565
C25: 5 | D25: E | E25: G | F25: 2.25 | H25: 2.7 | K25: =F25*H25 -> 6.075
C26: 6 | D26: F | E26: G | F26: 2.25 | H26: 2.7 | K26: =F26*H26 -> 6.075
C27: 7 | D27: C | E27: D | F27: 0.7 | H27: 2.7 | K27: =F27*H27 -> 1.89
C28: 7 | D28: D | E28: E | F28: 0.75 | H28: 0.72 | K28: =F28*H28 -> 0.54
C29: 7 | D29: E | E29: G | F29: 2.59 | H29: 2.7 | K29: =F29*H29 -> 6.993
C30: 8 | D30: A | E30: A' | F30: 0.5 | H30: 2.7 | K30: =F30*H30 -> 1.35
C31: 8 | D31: A' | E31: C | F31: 1.45 | H31: 2.32 | K31: =F31*H31 -> 3.364
I39: Total | J39: =J11 -> m2 | K39: =SUM(K11:K38) -> 146.205
A45: Elaboró | D45: Revisó | I45: Vo. Bo.
A46: ='PORTADA Y DATOS'!A11 -> Supervisor | D46: ='PORTADA Y DATOS'!A4 -> Dependencia/Contratante/Cliente | I46: ='PORTADA Y DATOS'!A7 -> Contratista
A47: ='PORTADA Y DATOS'!B11 -> Definido por parte contratante | D47: ='PORTADA Y DATOS'!C4 -> Luis Alberto Gamboa Ruelas | I47: ='PORTADA Y DATOS'!B7 -> Luis Alberto Gamboa Ruelas

Sheet MUR_REF_01
A1: NÚMEROS GENERADORES ACERO
A3: ='PORTADA Y DATOS'!A7 -> Contratista | B3: ='PORTADA Y DATOS'!B7 -> Luis Alberto Gamboa Ruelas | E3: ='PORTADA Y DATOS'!A6 -> Dirección | F3: ='PORTADA Y DATOS'!B6 -> Altata, Navolato, Sinaloa. | J3: =A1 -> NÚMEROS GENERADORES ACERO
A4: ='PORTADA Y DATOS'!A5 -> Obra | B4: ='PORTADA Y DATOS'!B5 -> Casa Altata | E4: ='PORTADA Y DATOS'!A4 -> Dependencia/Contratante/Cliente | H4: Logotipo | J4: 4
J5: Periodo
A6: ='PORTADA Y DATOS'!A10 -> Tipo de contrato | C6: Partida | E6: Refuerzo vertical en muro con varilla | I6: HOJA: 1 | J6: De: 11/10/2021 | K6: Al: 16/10/2021
A7: ='PORTADA Y DATOS'!B10 -> Precio Unitario | I7: DE: 1 | J7: ='PORTADA Y DATOS'!A9 -> Fecha de inicio | K7: ='PORTADA Y DATOS'!B9 -> Sin definir por contratista
A8: CLAVE | B8: CONCEPTO | C8: L O C A L I Z A C I O N | F8: LARGO | G8: ANCHO | H8: ALTO | I8: PZAS | J8: UNIDAD | K8: TOTAL
C9: EJE | D9: TRAMO
A10: Responsable de la empresa | F10: ='PORTADA Y DATOS'!B11 -> Definido por parte contratante
A11: MUR_REF_01 | B11: Refuerzo vertícal con varilla 3/8" @3 celdas, ahogada en concreto f'c:100kg/cm2 o según indicación estructural. Incluye material, mano de obra y todo lo necesario para su correcta ejecución. | C11: A | D11: 1 | E11: 8 | F11: 10.7 | H11: 2.7 | I11: =F11/0.85 -> 12.588235 | J11: mL | K11: =I11*H11 -> 33.988235
C12: B | D12: 3 | E12: 4 | F12: 0.95 | H12: 2.7 | I12: =F12/0.85 -> 1.1176471 | K12: =I12*H12 -> 3.0176471
C13: C | D13: 7 | E13: 8 | F13: 0.75 | H13: 2.7 | I13: =F13/0.85 -> 0.88235294 | K13: =I13*H13 -> 2.3823529
C14: D | D14: 2 | E14: 5 | F14: 3.3 | H14: 2.7 | I14: =F14/0.85 -> 3.8823529 | K14: =I14*H14 -> 10.482353
C15: D | D15: 6 | E15: 7 | F15: 3.35 | H15: 2.7 | I15: =F15/0.85 -> 3.9411765 | K15: =I15*H15 -> 10.641176
C16: E | D16: 1 | E16: 2 | F16: 1.15 | H16: 2.3 | I16: =F16/0.85 -> 1.3529412 | K16: =I16*H16 -> 3.1117647
C17: E | D17: 1 | E17: 2 | F17: 0.8 | H17: 2.7 | I17: =F17/0.85 -> 0.94117647 | K17: =I17*H17 -> 2.5411765
C18: F | D18: 5 | E18: 6 | F18: 1.15 | H18: 2.7 | I18: =F18/0.85 -> 1.3529412 | K18: =I18*H18 -> 3.6529412
C19: G | D19: 1 | E19: 7 | F19: 10.2 | H19: 2.7 | I19: =F19/0.85 -> 12 | K19: =I19*H19 -> 32.4
C20: 1 | D20: A | E20: G | F20: 7.5 | H20: 2.7 | I20: =F20/0.85 -> 8.8235294 | K20: =I20*H20 -> 23.823529
C21: 2 | D21: D | E21: E | F21: 1.05 | H21: 2.3 | I21: =F21/0.85 -> 1.2352941 | K21: =I21*H21 -> 2.8411765
C22: 2 | D22: E | E22: G | F22: 2.58 | H22: 2.7 | I22: =F22/0.85 -> 3.0352941 | K22: =I22*H22 -> 8.1952941
C23: 3 | D23: A | E23: A' | F23: 0.93 | H23: 0.9 | I23: =F23/0.85 -> 1.0941176 | K23: =I23*H23 -> 0.98470588
C24: 3 | D24: A' | E24: B | F24: 0.95 | H24: 2.7 | I24: =F24/0.85 -> 1.1176471 | K24: =I24*H24 -> 3.0176471
C25: 5 | D25: E | E25: G | F25: 2.25 | H25: 2.7 | I25: =F25/0.85 -> 2.6470588 | K25: =I25*H25 -> 7.1470588
C26: 6 | D26: F | E26: G | F26: 2.25 | H26: 2.7 | I26: =F26/0.85 -> 2.6470588 | K26: =I26*H26 -> 7.1470588
C27: 7 | D27: C | E27: D | F27: 0.7 | H27: 2.7 | I27: =F27/0.85 -> 0.82352941 | K27: =I27*H27 -> 2.2235294
C28: 7 | D28: D | E28: E | F28: 0.75 | H28: 0.72 | I28: =F28/0.85 -> 0.88235294 | K28: =I28*H28 -> 0.63529412
C29: 7 | D29: E | E29: G | F29: 2.59 | H29: 2.7 | I29: =F29/0.85 -> 3.0470588 | K29: =I29*H29 -> 8.2270588
C30: 8 | D30: A | E30: A' | F30: 0.5 | H30: 2.7 | I30: =F30/0.85 -> 0.58823529 | K30: =I30*H30 -> 1.5882353
C31: 8 | D31: A' | E31: C | F31: 1.45 | H31: 2.32 | I31: =F31/0.85 -> 1.7058824 | K31: =I31*H31 -> 3.9576471
I39: Total | J39: =J11 -> mL | K39: =SUM(K11:K38) -> 172.00588
A45: Elaboró | D45: Revisó | I45: Vo. Bo.
A46: ='PORTADA Y DATOS'!A11 -> Supervisor | D46: ='PORTADA Y DATOS'!A4 -> Dependencia/Contratante/Cliente | I46: ='PORTADA Y DATOS'!A7 -> Contratista
A47: ='PORTADA Y DATOS'!B11 -> Definido por parte contratante | D47: ='PORTADA Y DATOS'!C4 -> Luis Alberto Gamboa Ruelas | I47: ='PORTADA Y DATOS'!B7 -> Luis Alberto Gamboa Ruelas

Sheet MUR_PRE_EP_01
A1: NÚMEROS GENERADORES ACERO
A3: ='PORTADA Y DATOS'!A7 -> Contratista | B3: ='PORTADA Y DATOS'!B7 -> Luis Alberto Gamboa Ruelas | E3: ='PORTADA Y DATOS'!A6 -> Dirección | F3: ='PORTADA Y DATOS'!B6 -> Altata, Navolato, Sinaloa. | J3: =A1 -> NÚMEROS GENERADORES ACERO
A4: ='PORTADA Y DATOS'!A5 -> Obra | B4: ='PORTADA Y DATOS'!B5 -> Casa Altata | E4: ='PORTADA Y DATOS'!A4 -> Dependencia/Contratante/Cliente | H4: Logotipo | J4: 4
J5: Periodo
A6: ='PORTADA Y DATOS'!A10 -> Tipo de contrato | C6: Partida | E6: Pretíl en EP con block 12x20x40 | I6: HOJA: 1 | J6: De: 11/10/2021 | K6: Al: 16/10/2021
A7: ='PORTADA Y DATOS'!B10 -> Precio Unitario | I7: DE: 1 | J7: ='PORTADA Y DATOS'!A9 -> Fecha de inicio | K7: ='PORTADA Y DATOS'!B9 -> Sin definir por contratista
A8: CLAVE | B8: CONCEPTO | C8: L O C A L I Z A C I O N | F8: LARGO | G8: ANCHO | H8: ALTO | I8: PZAS (CARAS) | J8: UNIDAD | K8: TOTAL
C9: EJE | D9: TRAMO
A10: Responsable de la empresa | F10: ='PORTADA Y DATOS'!B11 -> Definido por parte contratante
A11: MUR_PRE_EP_01 | B11: Pretíl en EP con block 12x20x40 asentado con mortero/arena 1:5. H=10cm, incluye material, mano de obra y todo lo necesario para su correcta ejecución. | C11: A | D11: 3 | E11: 8 | F11: 8.38 | I11: 1 | J11: mL | K11: =F11*I11 -> 8.38
C12: B | D12: 3 | E12: 4 | F12: 0.76 | I12: 1 | K12: =F12*I12 -> 0.76
C13: D | D13: 2 | E13: 4 | F13: 1.32 | I13: 1 | K13: =F13*I13 -> 1.32
C14: E | D14: 1 | E14: 2 | F14: 1.8 | I14: 1 | K14: =F14*I14 -> 1.8
C15: G | D15: 1 | E15: 7 | F15: 10.25 | I15: 1 | K15: =F15*I15 -> 10.25
C16: 1 | D16: E | E16: G | F16: 2.58 | I16: 1 | K16: =F16*I16 -> 2.58
C17: 2 | D17: D | E17: E | F17: 0.72 | I17: 1 | K17: =F17*I17 -> 0.72
C18: 3 | D18: A | E18: B | F18: 2.75 | I18: 1 | K18: =F18*I18 -> 2.75
C19: 4 | D19: B | E19: D | F19: 1.45 | I19: 1 | K19: =F19*I19 -> 1.45
C20: 7 | D20: C | E20: G | F20: 3.68 | I20: 1 | K20: =F20*I20 -> 3.68
C21: 8 | D21: A | E21: C | F21: 3.8 | I21: 1 | K21: =F21*I21 -> 3.8
I39: Total | J39: =J11 -> mL | K39: =SUM(K11:K38) -> 37.49
A44: Elaboró | D44: Revisó | I44: Vo. Bo.
A45: ='PORTADA Y DATOS'!A11 -> Supervisor | D45: ='PORTADA Y DATOS'!A4 -> Dependencia/Contratante/Cliente | I45: ='PORTADA Y DATOS'!A7 -> Contratista
A46: ='PORTADA Y DATOS'!B11 -> Definido por parte contratante | D46: ='PORTADA Y DATOS'!C4 -> Luis Alberto Gamboa Ruelas | I46: ='PORTADA Y DATOS'!B7 -> Luis Alberto Gamboa Ruelas

Sheet CAS_HAC_K1
A1: NÚMEROS GENERADORES ACERO
A3: ='PORTADA Y DATOS'!A7 -> Contratista | B3: ='PORTADA Y DATOS'!B7 -> Luis Alberto Gamboa Ruelas | E3: ='PORTADA Y DATOS'!A6 -> Dirección | F3: ='PORTADA Y DATOS'!B6 -> Altata, Navolato, Sinaloa. | J3: =A1 -> NÚMEROS GENERADORES ACERO
A4: ='PORTADA Y DATOS'!A5 -> Obra | B4: ='PORTADA Y DATOS'!B5 -> Casa Altata | E4: ='PORTADA Y DATOS'!A4 -> Dependencia/Contratante/Cliente | H4: Logotipo | J4: 4
J5: Periodo
A6: ='PORTADA Y DATOS'!A10 -> Tipo de contrato | C6: Partida | E6: Habilitado de acero en castillo K-1 | I6: HOJA: 1 | J6: De: 11/10/2021 | K6: Al: 16/10/2021
A7: ='PORTADA Y DATOS'!B10 -> Precio Unitario | I7: DE: 1 | J7: ='PORTADA Y DATOS'!A9 -> Fecha de inicio | K7: ='PORTADA Y DATOS'!B9 -> Sin definir por contratista
A8: CLAVE | B8: CONCEPTO | C8: L O C A L I Z A C I O N | F8: LARGO | G8: ANCHO | H8: ALTO | I8: PZAS | J8: UNIDAD | K8: TOTAL
C9: EJE | D9: TRAMO
A10: Responsable de la empresa | F10: ='PORTADA Y DATOS'!B11 -> Definido por parte contratante
A11: CAS_HAC_K1 | B11: Habilitado de acero en castillo K-1 con armex 15x15-4. Incluye colocación, material y lo necesario para su correcta ejecución. | C11: A | D11: 1 | E11: 8 | H11: 3.32 | I11: 5 | J11: mL | K11: =H11*I11 -> 16.6
C12: B | D12: 1 | E12: 4 | H12: 3.32 | I12: 3 | K12: =H12*I12 -> 9.96
C13: C | D13: 7 | E13: 8 | H13: 3.32 | I13: 1 | K13: =H13*I13 -> 3.32
C14: D | D14: 2 | E14: 7 | H14: 3.32 | I14: 5 | K14: =H14*I14 -> 16.6
C15: D | D15: 7 | H15: 3.32 | I15: =F15/0.85 -> 0 | K15: =H15*I15 -> 0
C16: E | D16: 1 | E16: 2 | H16: 3.32 | I16: 3 | K16: =H16*I16 -> 9.96
C17: F | D17: 5 | E17: 6 | H17: 3.32 | I17: 3 | K17: =H17*I17 -> 9.96
C18: G | D18: 1 | E18: 8 | H18: 3.32 | I18: 7 | K18: =H18*I18 -> 23.24
C19: 3 | D19: A | E19: B | H19: 3.32 | I19: 2 | K19: =H19*I19 -> 6.64
C20: 8' | D20: A' | H20: 3.32 | I20: 2 | K20: =H20*I20 -> 6.64
I39: Total | J39: =J11 -> mL | K39: =SUM(K11:K38) -> 102.92
A45: Elaboró | D45: Revisó | I45: Vo. Bo.
A46: ='PORTADA Y DATOS'!A11 -> Supervisor | D46: ='PORTADA Y DATOS'!A4 -> Dependencia/Contratante/Cliente | I46: ='PORTADA Y DATOS'!A7 -> Contratista
A47: ='PORTADA Y DATOS'!B11 -> Definido por parte contratante | D47: ='PORTADA Y DATOS'!C4 -> Luis Alberto Gamboa Ruelas | I47: ='PORTADA Y DATOS'!B7 -> Luis Alberto Gamboa Ruelas

Sheet CAS_HAC_K2
A1: NÚMEROS GENERADORES ACERO
A3: ='PORTADA Y DATOS'!A7 -> Contratista | B3: ='PORTADA Y DATOS'!B7 -> Luis Alberto Gamboa Ruelas | E3: ='PORTADA Y DATOS'!A6 -> Dirección | F3: ='PORTADA Y DATOS'!B6 -> Altata, Navolato, Sinaloa. | J3: =A1 -> NÚMEROS GENERADORES ACERO
A4: ='PORTADA Y DATOS'!A5 -> Obra | B4: ='PORTADA Y DATOS'!B5 -> Casa Altata | E4: ='PORTADA Y DATOS'!A4 -> Dependencia/Contratante/Cliente | H4: Logotipo | J4: 4
J5: Periodo
A6: ='PORTADA Y DATOS'!A10 -> Tipo de contrato | C6: Partida | E6: Habilitado de acero en castillo K-2 | I6: HOJA: 1 | J6: De: 11/10/2021 | K6: Al: 16/10/2021
A7: ='PORTADA Y DATOS'!B10 -> Precio Unitario | I7: DE: 1 | J7: ='PORTADA Y DATOS'!A9 -> Fecha de inicio | K7: ='PORTADA Y DATOS'!B9 -> Sin definir por contratista
A8: CLAVE | B8: CONCEPTO | C8: L O C A L I Z A C I O N | F8: LARGO | G8: ANCHO | H8: ALTO | I8: PZAS | J8: UNIDAD | K8: TOTAL
C9: EJE | D9: TRAMO
A10: Responsable de la empresa | F10: ='PORTADA Y DATOS'!B11 -> Definido por parte contratante
A11: CAS_HAC_K2 | B11: Habilitado de acero en castillo K-2 con armex 15x20-4. Incluye colocación, material y lo necesario para su correcta ejecución. | C11: 7 | D11: C | E11: G | H11: 3.32 | I11: 3 | J11: mL | K11: =H11*I11 -> 9.96
I39: Total | J39: =J11 -> mL | K39: =SUM(K11:K38) -> 9.96
A45: Elaboró | D45: Revisó | I45: Vo. Bo.
A46: ='PORTADA Y DATOS'!A11 -> Supervisor | D46: ='PORTADA Y DATOS'!A4 -> Dependencia/Contratante/Cliente | I46: ='PORTADA Y DATOS'!A7 -> Contratista
A47: ='PORTADA Y DATOS'!B11 -> Definido por parte contratante | D47: ='PORTADA Y DATOS'!C4 -> Luis Alberto Gamboa Ruelas | I47: ='PORTADA Y DATOS'!B7 -> Luis Alberto Gamboa Ruelas

Sheet CAS_HCC_01
A1: NÚMEROS GENERADORES ACERO
A3: ='PORTADA Y DATOS'!A7 -> Contratista | B3: ='PORTADA Y DATOS'!B7 -> Luis Alberto Gamboa Ruelas | E3: ='PORTADA Y DATOS'!A6 -> Dirección | F3: ='PORTADA Y DATOS'!B6 -> Altata, Navolato, Sinaloa. | J3: =A1 -> NÚMEROS GENERADORES ACERO
A4: ='PORTADA Y DATOS'!A5 -> Obra | B4: ='PORTADA Y DATOS'!B5 -> Casa Altata | E4: ='PORTADA Y DATOS'!A4 -> Dependencia/Contratante/Cliente | H4: Logotipo | J4: 4
J5: Periodo
A6: ='PORTADA Y DATOS'!A10 -> Tipo de contrato | C6: Partida | E6: Habilitado de cimbra para castillos K-1 | I6: HOJA: 1 | J6: De: 11/10/2021 | K6: Al: 16/10/2021
A7: ='PORTADA Y DATOS'!B10 -> Precio Unitario | I7: DE: 1 | J7: ='PORTADA Y DATOS'!A9 -> Fecha de inicio | K7: ='PORTADA Y DATOS'!B9 -> Sin definir por contratista
A8: CLAVE | B8: CONCEPTO | C8: L O C A L I Z A C I O N | F8: LARGO | G8: ANCHO | H8: ALTO | I8: PZAS | J8: UNIDAD | K8: TOTAL
C9: EJE | D9: TRAMO
A10: Responsable de la empresa | F10: ='PORTADA Y DATOS'!B11 -> Definido por parte contratante
A11: CAS_HCC_01 | B11: Habilitado de cimbra para castillos K-1 a centro de muro, con triplay de 3/4", fajillas y bastones de 3x3x8' como puntal. Incluye material y lo necesario para su correcta ejecución. | C11: A | D11: 1 | E11: 8 | H11: 3.32 | I11: 5 | J11: mL | K11: =H11*I11 -> 16.6
C12: B | D12: 1 | E12: 4 | H12: 3.32 | I12: 3 | K12: =H12*I12 -> 9.96
C13: C | D13: 7 | E13: 8 | H13: 3.32 | I13: 1 | K13: =H13*I13 -> 3.32
C14: D | D14: 2 | E14: 7 | H14: 3.32 | I14: 5 | K14: =H14*I14 -> 16.6
C15: D | D15: 7 | H15: 3.32 | I15: =F15/0.85 -> 0 | K15: =H15*I15 -> 0
C16: E | D16: 1 | E16: 2 | H16: 3.32 | I16: 3 | K16: =H16*I16 -> 9.96
C17: F | D17: 5 | E17: 6 | H17: 3.32 | I17: 3 | K17: =H17*I17 -> 9.96
C18: G | D18: 1 | E18: 8 | H18: 3.32 | I18: 7 | K18: =H18*I18 -> 23.24
C19: 3 | D19: A | E19: B | H19: 3.32 | I19: 2 | K19: =H19*I19 -> 6.64
C20: 8' | D20: A' | H20: 3.32 | I20: 2 | K20: =H20*I20 -> 6.64
I39: Total | J39: =J11 -> mL | K39: =SUM(K11:K38) -> 102.92
A45: Elaboró | D45: Revisó | I45: Vo. Bo.
A46: ='PORTADA Y DATOS'!A11 -> Supervisor | D46: ='PORTADA Y DATOS'!A4 -> Dependencia/Contratante/Cliente | I46: ='PORTADA Y DATOS'!A7 -> Contratista
A47: ='PORTADA Y DATOS'!B11 -> Definido por parte contratante | D47: ='PORTADA Y DATOS'!C4 -> Luis Alberto Gamboa Ruelas | I47: ='PORTADA Y DATOS'!B7 -> Luis Alberto Gamboa Ruelas

Sheet CAS_HCC_02
A1: NÚMEROS GENERADORES ACERO
A3: ='PORTADA Y DATOS'!A7 -> Contratista | B3: ='PORTADA Y DATOS'!B7 -> Luis Alberto Gamboa Ruelas | E3: ='PORTADA Y DATOS'!A6 -> Dirección | F3: ='PORTADA Y DATOS'!B6 -> Altata, Navolato, Sinaloa. | J3: =A1 -> NÚMEROS GENERADORES ACERO
